[2021-10-29 01:19:23,395] {taskinstance.py:1035} INFO - Dependencies all met for <TaskInstance: my_dag.inaccurate scheduled__2021-10-28T00:00:00+00:00 [queued]>
[2021-10-29 01:19:23,589] {taskinstance.py:1035} INFO - Dependencies all met for <TaskInstance: my_dag.inaccurate scheduled__2021-10-28T00:00:00+00:00 [queued]>
[2021-10-29 01:19:23,589] {taskinstance.py:1241} INFO - 
--------------------------------------------------------------------------------
[2021-10-29 01:19:23,589] {taskinstance.py:1242} INFO - Starting attempt 1 of 1
[2021-10-29 01:19:23,589] {taskinstance.py:1243} INFO - 
--------------------------------------------------------------------------------
[2021-10-29 01:19:23,696] {taskinstance.py:1262} INFO - Executing <Task(BashOperator): inaccurate> on 2021-10-28 00:00:00+00:00
[2021-10-29 01:19:23,836] {standard_task_runner.py:52} INFO - Started process 1009 to run task
[2021-10-29 01:19:23,848] {standard_task_runner.py:76} INFO - Running: ['***', 'tasks', 'run', 'my_dag', 'inaccurate', 'scheduled__2021-10-28T00:00:00+00:00', '--job-id', '30', '--raw', '--subdir', 'DAGS_FOLDER/my_dag.py', '--cfg-path', '/tmp/tmpcfh__3g_', '--error-file', '/tmp/tmp4mo9nuq2']
[2021-10-29 01:19:24,058] {standard_task_runner.py:77} INFO - Job 30: Subtask inaccurate
[2021-10-29 01:19:24,914] {logging_mixin.py:109} INFO - Running <TaskInstance: my_dag.inaccurate scheduled__2021-10-28T00:00:00+00:00 [running]> on host 28ad64d5edf5
[2021-10-29 01:19:25,766] {taskinstance.py:1414} INFO - Exporting the following env vars:
AIRFLOW_CTX_DAG_OWNER=***
AIRFLOW_CTX_DAG_ID=my_dag
AIRFLOW_CTX_TASK_ID=inaccurate
AIRFLOW_CTX_EXECUTION_DATE=2021-10-28T00:00:00+00:00
AIRFLOW_CTX_DAG_RUN_ID=scheduled__2021-10-28T00:00:00+00:00
[2021-10-29 01:19:25,767] {subprocess.py:62} INFO - Tmp dir root location: 
 /tmp
[2021-10-29 01:19:25,767] {subprocess.py:74} INFO - Running command: ['bash', '-c', "echo 'inaccurate'"]
[2021-10-29 01:19:26,062] {subprocess.py:85} INFO - Output:
[2021-10-29 01:19:26,165] {subprocess.py:89} INFO - inaccurate
[2021-10-29 01:19:26,166] {subprocess.py:93} INFO - Command exited with return code 0
[2021-10-29 01:19:26,490] {taskinstance.py:1280} INFO - Marking task as SUCCESS. dag_id=my_dag, task_id=inaccurate, execution_date=20211028T000000, start_date=20211029T011923, end_date=20211029T011926
[2021-10-29 01:19:26,617] {local_task_job.py:154} INFO - Task exited with return code 0
[2021-10-29 01:19:26,966] {local_task_job.py:264} INFO - 0 downstream tasks scheduled from follow-on schedule check
